<?xml version="1.0"?>
<robot name="wheel" xmlns:xacro="http://wiki.ros.org/xacro" xmlns:gz="http://gazebosim.org/schema">

    <xacro:property name="M_PI" value="3.1415926535897931" />
    <!-- Wheels -->
    <xacro:property name="mecanum_wheel_radius" value="0.127" />
    <xacro:property name="mecanum_wheel_height" value="0.087" />
    <xacro:property name="mecanum_wheel_mass" value="6.5" /> <!-- in kg-->


    <xacro:macro name="cylinder_inertia" params="m r h">
        <inertia ixx="${m*(3*r*r+h*h)/12}" ixy="0" ixz="0"
            iyy="${m*r*r/2}" iyz="0"
            izz="${m*(3*r*r+h*h)/12}" />
    </xacro:macro>

    <xacro:macro name="rbrobout_mecanum_wheel" params="prefix parent xyz reflect hq gazebo_classic:=false gazebo_ignition:=false">

        <joint name="${prefix}wheel_joint" type="continuous">
            <parent link="${parent}" />
            <child link="${prefix}wheel_link" />
            <xacro:if value="${gazebo_classic or gazebo_ignition}">
                <xacro:if value="${reflect}">
                    <origin xyz="${xyz}" rpy="0.0 0.0 -${PI/4}"/>
                </xacro:if>
                <xacro:unless value="${reflect}">
                    <origin xyz="${xyz}" rpy="0.0 0.0 ${PI/4}"/>
                </xacro:unless>
            </xacro:if>
            <xacro:unless value="${gazebo_classic or gazebo_ignition}">
                <origin xyz="${xyz}" rpy="0.0 0.0 0.0"/>
            </xacro:unless>
            <limit effort="100000" velocity="100" />
            <axis xyz="0 1 0"/>
        </joint>

        <link name="${prefix}wheel_link">
            <xacro:unless value="${gazebo_classic or gazebo_ignition}">
                <visual>
                    <xacro:if value="${hq}">
                        <xacro:if value="${reflect}">
                        <origin xyz="0 0 0" rpy="${PI/2} 0 0" />
                            <geometry>
                                <mesh
                                    filename="package://arena_robots/robots/rbvogui/meshes/wheels/mecanum_wheel/robout_wheel.stl" />
                            </geometry>
                        </xacro:if>
                        <xacro:unless value="${reflect}">
                        <origin xyz="0 0 0" rpy="${-PI/2} 0 0" />
                            <geometry>
                                <mesh
                                    filename="package://arena_robots/robots/rbvogui/meshes/wheels/mecanum_wheel/robout_wheel.stl" />
                            </geometry>
                        </xacro:unless>
                    </xacro:if>

                    <xacro:unless value="${hq}">
                        <origin xyz="0 0 0" rpy="0 0 0" />
                        <geometry>
                            <sphere radius="${mecanum_wheel_radius}" />
                        </geometry>
                    </xacro:unless>

                    <material name="darkgrey">
                        <color rgba="0.2 0.2 0.2 1" />
                    </material>
                </visual>
            </xacro:unless>

            <collision>
                <origin xyz="0 0 0" rpy="0 0 0" />
                <geometry>
                    <sphere radius="${mecanum_wheel_radius}" />
                </geometry>
            </collision>

            <inertial>
                <mass value="${mecanum_wheel_mass}" />
                <origin xyz="0 0 0" />
                <xacro:cylinder_inertia m="${mecanum_wheel_mass}" r="${mecanum_wheel_radius}"
                    h="${mecanum_wheel_height}" />
            </inertial>
        </link>

        <xacro:if value="${gazebo_classic or gazebo_ignition}">

            <gazebo reference="${prefix}wheel_link">
                <collision>
                    <surface>
                        <friction>
                            <ode>
                                <mu>1.0</mu>
                                <mu2>0.0</mu2>
                                <xacro:if value="${reflect}">
                                    <fdir1 gz:expressed_in="${parent}">1 0 0</fdir1>
                                </xacro:if>
                                <xacro:unless value="${reflect}">
                                    <fdir1 gz:expressed_in="${parent}">1 0 0</fdir1>
                                </xacro:unless>
                            </ode>
                        </friction>
                    </surface>
                </collision>
            </gazebo>

            <joint name="${prefix}visual_wheel_joint" type="fixed">
                <parent link="${parent}" />
                <child link="${prefix}visual_wheel_link" />
                <origin xyz="${xyz}"/>
            </joint>

            <link name="${prefix}visual_wheel_link">
                <visual>
                    <xacro:if value="${hq}">
                        <xacro:if value="${reflect}">
                        <origin xyz="0 0 0" rpy="${PI/2} 0 0" />
                            <geometry>
                                <mesh
                                    filename="package://arena_robots/robots/rbvogui/meshes/wheels/mecanum_wheel/robout_wheel.stl" />
                            </geometry>
                        </xacro:if>
                        <xacro:unless value="${reflect}">
                        <origin xyz="0 0 0" rpy="${-PI/2} 0 0" />
                            <geometry>
                                <mesh
                                    filename="package://arena_robots/robots/rbvogui/meshes/wheels/mecanum_wheel/robout_wheel.stl" />
                            </geometry>
                        </xacro:unless>
                    </xacro:if>

                    <xacro:unless value="${hq}">
                        <origin xyz="0 0 0" rpy="0 0 0" />
                        <geometry>
                            <sphere radius="${mecanum_wheel_radius}" />
                        </geometry>
                    </xacro:unless>

                    <material name="darkgrey">
                        <color rgba="0.2 0.2 0.2 1" />
                    </material>
                </visual>

            </link>
        </xacro:if>

    </xacro:macro>
</robot>
